<?xml version="1.0" ?>
<robot name="waker_wire">

<material name="silver">
  <color rgba="0.700 0.700 0.700 1.000"/>
</material>

<link name="base_link">
  <inertial>
    <origin xyz="-0.020703544507678903 0.0012128178735020354 0.01637530483830482" rpy="0 0 0"/>
    <mass value="0.03139999999999999"/>
    <inertia ixx="1.1121134972646436e-06" iyy="5.233333333333262e-06" izz="4.252053169401757e-06" ixy="-2.117582368135751e-22" iyz="2.117582368135751e-22" ixz="-9.732103314375617e-09"/>
  </inertial>
  <visual>
    <origin xyz="0 0 0" rpy="0 0 0"/>
    <geometry>
      <mesh filename="meshes/base_link.stl" scale="0.001 0.001 0.001"/>
    </geometry>
    <material name="silver"/>
    <material/>
  </visual>
  <collision>
    <origin xyz="0 0 0" rpy="0 0 0"/>
    <geometry>
      <mesh filename="meshes/base_link.stl" scale="0.001 0.001 0.001"/>
    </geometry>
  </collision>
</link>

<link name="A_link1">
  <inertial>
    <origin xyz="0.008866195567032172 -1.821264979647106e-07 -0.00881161293585304" rpy="0 0 0"/>
    <mass value="0.004906250073108822"/>
    <inertia ixx="1.4233864366705368e-07" iyy="2.6575521990891076e-07" izz="1.4385928487978826e-07" ixy="1.3234889800848443e-22" iyz="1.3234889800848443e-23" ixz="1.2265389907820598e-07"/>
  </inertial>
  <visual>
    <origin xyz="-0.018822 -0.001213 0.009412" rpy="0 0 0"/>
    <geometry>
      <mesh filename="meshes/A_link1.stl" scale="0.001 0.001 0.001"/>
    </geometry>
    <material name="silver"/>
    <material/>
  </visual>
  <collision>
    <origin xyz="-0.018822 -0.001213 0.009412" rpy="0 0 0"/>
    <geometry>
      <mesh filename="meshes/A_link1.stl" scale="0.001 0.001 0.001"/>
    </geometry>
  </collision>
</link>

<link name="E_link1">
  <inertial>
    <origin xyz="0.02837172808810274 -1.8212649794844757e-07 -0.028196329432276" rpy="0 0 0"/>
    <mass value="0.0157"/>
    <inertia ixx="4.2098782032903755e-06" iyy="8.406041666667092e-06" izz="4.261580130043674e-06" ixy="-1.469602163486211e-19" iyz="-7.517417406881916e-20" ixz="4.170232376660676e-06"/>
  </inertial>
  <visual>
    <origin xyz="0.042486 -0.001213 0.056989" rpy="0 0 0"/>
    <geometry>
      <mesh filename="meshes/E_link1.stl" scale="0.001 0.001 0.001"/>
    </geometry>
    <material name="silver"/>
    <material/>
  </visual>
  <collision>
    <origin xyz="0.042486 -0.001213 0.056989" rpy="0 0 0"/>
    <geometry>
      <mesh filename="meshes/E_link1.stl" scale="0.001 0.001 0.001"/>
    </geometry>
  </collision>
</link>

<link name="L1_link1">
  <inertial>
    <origin xyz="0.010628820453684795 -1.821264979647106e-07 -0.007037818544703008" rpy="0 0 0"/>
    <mass value="0.004906250000000002"/>
    <inertia ixx="1.423386377618992e-07" iyy="2.657552083333387e-07" izz="1.4385927890476808e-07" ixy="1.3234889800848443e-23" iyz="2.771055052052643e-23" ixz="1.2265389344284634e-07"/>
  </inertial>
  <visual>
    <origin xyz="0.000673 -0.001213 -0.006437" rpy="0 0 0"/>
    <geometry>
      <mesh filename="meshes/L1_link1.stl" scale="0.001 0.001 0.001"/>
    </geometry>
    <material name="silver"/>
    <material/>
  </visual>
  <collision>
    <origin xyz="0.000673 -0.001213 -0.006437" rpy="0 0 0"/>
    <geometry>
      <mesh filename="meshes/L1_link1.stl" scale="0.001 0.001 0.001"/>
    </geometry>
  </collision>
</link>

<link name="B_link1">
  <inertial>
    <origin xyz="-0.03693298914206055 -1.8212649796557796e-07 -0.015564012121471474" rpy="0 0 0"/>
    <mass value="0.015700001169741153"/>
    <inertia ixx="9.742182848243483e-07" iyy="8.406042297839456e-06" izz="7.497240684555777e-06" ixy="-1.0587911840678754e-22" iyz="-1.0587911840678754e-22" ixz="-2.5988562122629307e-06"/>
  </inertial>
  <visual>
    <origin xyz="-0.01706 -0.001213 0.011185" rpy="0 0 0"/>
    <geometry>
      <mesh filename="meshes/B_link1.stl" scale="0.001 0.001 0.001"/>
    </geometry>
    <material name="silver"/>
    <material/>
  </visual>
  <collision>
    <origin xyz="-0.01706 -0.001213 0.011185" rpy="0 0 0"/>
    <geometry>
      <mesh filename="meshes/B_link1.stl" scale="0.001 0.001 0.001"/>
    </geometry>
  </collision>
</link>

<link name="D_link1">
  <inertial>
    <origin xyz="-0.03693261396737039 -1.821264979694811e-07 -0.015563806446053659" rpy="0 0 0"/>
    <mass value="0.0157"/>
    <inertia ixx="9.742182047942614e-07" iyy="8.406041666666632e-06" izz="7.497240128539084e-06" ixy="-1.0654086289682996e-21" iyz="-1.0587911840678754e-22" ixz="-2.598856016258386e-06"/>
  </inertial>
  <visual>
    <origin xyz="-0.034792 -0.001213 0.028808" rpy="0 0 0"/>
    <geometry>
      <mesh filename="meshes/D_link1.stl" scale="0.001 0.001 0.001"/>
    </geometry>
    <material name="silver"/>
    <material/>
  </visual>
  <collision>
    <origin xyz="-0.034792 -0.001213 0.028808" rpy="0 0 0"/>
    <geometry>
      <mesh filename="meshes/D_link1.stl" scale="0.001 0.001 0.001"/>
    </geometry>
  </collision>
</link>

<link name="C_link1">
  <inertial>
    <origin xyz="0.0071037403437694754 -1.8212649796644532e-07 -0.010584461772103579" rpy="0 0 0"/>
    <mass value="0.004906249999999999"/>
    <inertia ixx="1.4233863588141398e-07" iyy="2.657552083348247e-07" izz="1.4385928078593318e-07" ixy="1.0587911840678754e-22" iyz="1.0587911840678754e-22" ixz="1.2265389343073663e-07"/>
  </inertial>
  <visual>
    <origin xyz="0.058456 -0.001213 0.037593" rpy="0 0 0"/>
    <geometry>
      <mesh filename="meshes/C_link1.stl" scale="0.001 0.001 0.001"/>
    </geometry>
    <material name="silver"/>
    <material/>
  </visual>
  <collision>
    <origin xyz="0.058456 -0.001213 0.037593" rpy="0 0 0"/>
    <geometry>
      <mesh filename="meshes/C_link1.stl" scale="0.001 0.001 0.001"/>
    </geometry>
  </collision>
</link>

<link name="D_link1">
  <inertial>
    <origin xyz="0.03858338603262961 -1.821264979694811e-07 0.010844193553946342" rpy="0 0 0"/>
    <mass value="0.0157"/>
    <inertia ixx="9.742182047942614e-07" iyy="8.406041666666632e-06" izz="7.497240128539084e-06" ixy="-1.0654086289682996e-21" iyz="-1.0587911840678754e-22" ixz="-2.598856016258386e-06"/>
  </inertial>
  <visual>
    <origin xyz="0.040724 -0.001213 0.055216" rpy="0 0 0"/>
    <geometry>
      <mesh filename="meshes/D_link1.stl" scale="0.001 0.001 0.001"/>
    </geometry>
    <material name="silver"/>
    <material/>
  </visual>
  <collision>
    <origin xyz="0.040724 -0.001213 0.055216" rpy="0 0 0"/>
    <geometry>
      <mesh filename="meshes/D_link1.stl" scale="0.001 0.001 0.001"/>
    </geometry>
  </collision>
</link>

<joint name="Rigid_1" type="fixed">
  <origin xyz="0.019495 0.0 -0.015849" rpy="0 0 0"/>
  <parent link="L1_link1"/>
  <child link="A_link1"/>
</joint>

<joint name="Rigid_2" type="fixed">
  <origin xyz="0.01597 0.0 -0.019396" rpy="0 0 0"/>
  <parent link="C_link1"/>
  <child link="E_link1"/>
</joint>

<joint name="Rigid_3" type="fixed">
  <origin xyz="-0.000673 0.001213 0.006437" rpy="0 0 0"/>
  <parent link="base_link"/>
  <child link="L1_link1"/>
</joint>

<joint name="Revolute_4" type="continuous">
  <origin xyz="0.017733 0.0 -0.017622" rpy="0 0 0"/>
  <parent link="L1_link1"/>
  <child link="B_link1"/>
  <axis xyz="-0.0 1.0 -0.0"/>
</joint>
<transmission name="Revolute_4_tran">
  <type>transmission_interface/SimpleTransmission</type>
  <joint name="Revolute_4">
    <hardwareInterface>PositionJointInterface</hardwareInterface>
  </joint>
  <actuator name="Revolute_4_actr">
    <hardwareInterface>PositionJointInterface</hardwareInterface>
    <mechanicalReduction>1</mechanicalReduction>
  </actuator>
</transmission>

<joint name="Revolute_5" type="continuous">
  <origin xyz="-0.059546 0.0 -0.045804" rpy="0 0 0"/>
  <parent link="A_link1"/>
  <child link="D_link1"/>
  <axis xyz="-0.0 1.0 -0.0"/>
</joint>
<transmission name="Revolute_5_tran">
  <type>transmission_interface/SimpleTransmission</type>
  <joint name="Revolute_5">
    <hardwareInterface>PositionJointInterface</hardwareInterface>
  </joint>
  <actuator name="Revolute_5_actr">
    <hardwareInterface>PositionJointInterface</hardwareInterface>
    <mechanicalReduction>1</mechanicalReduction>
  </actuator>
</transmission>

<joint name="Revolute_6" type="continuous">
  <origin xyz="-0.075516 0.0 -0.026408" rpy="0 0 0"/>
  <parent link="B_link1"/>
  <child link="C_link1"/>
  <axis xyz="-0.0 1.0 -0.0"/>
</joint>
<transmission name="Revolute_6_tran">
  <type>transmission_interface/SimpleTransmission</type>
  <joint name="Revolute_6">
    <hardwareInterface>PositionJointInterface</hardwareInterface>
  </joint>
  <actuator name="Revolute_6_actr">
    <hardwareInterface>PositionJointInterface</hardwareInterface>
    <mechanicalReduction>1</mechanicalReduction>
  </actuator>
</transmission>

<joint name="Revolute_7" type="continuous">
  <origin xyz="0.017732 0.0 -0.017623" rpy="0 0 0"/>
  <parent link="C_link1"/>
  <child link="D_link1"/>
  <axis xyz="-0.0 1.0 -0.0"/>
</joint>
<transmission name="Revolute_7_tran">
  <type>transmission_interface/SimpleTransmission</type>
  <joint name="Revolute_7">
    <hardwareInterface>PositionJointInterface</hardwareInterface>
  </joint>
  <actuator name="Revolute_7_actr">
    <hardwareInterface>PositionJointInterface</hardwareInterface>
    <mechanicalReduction>1</mechanicalReduction>
  </actuator>
</transmission>

</robot>
